Workbook

Sheet CWL 1
B1: nome | C1: pos | D1: th | E1: stelle | F1: pos | G1: th | H1: stelle | I1: pos | J1: th | K1: stelle | L1: pos | M1: th | N1: stelle | O1: pos | P1: th | Q1: stelle | R1: pos | S1: th | T1: stelle | U1: pos | V1: th | W1: stelle | X1: pos | Y1: th | Z1: stelle | AA1: pos | AB1: th | AC1: stelle
A2: 16 | B2: xblade | C2: 0 | D2: -4 | E2: 3 | I2: 0 | J2: 0 | K2: 2
A3: 15 | B3: marcojk | F3: 0 | G3: 2 | H3: 2
A4: 15 | B4: dado | C4: 0 | D4: -3 | E4: 3 | F4: 0 | G4: 0 | H4: 3 | I4: 0 | J4: 2 | K4: 2
A5: 13 | B5: bigmc | C5: -1 | D5: -2 | E5: 3 | F5: -3 | G5: 2 | H5: 2 | I5: -2 | J5: 2 | K5: 1
A6: 12 | B6: luigi01 | C6: 2 | D6: 0 | E6: 2 | F6: 0 | G6: 3 | H6: 1 | I6: -14 | J6: 0 | K6: 3
A7: 12 13 | B7: piegian99 | C7: 2 | D7: -1 | E7: 3 | F7: 0 | G7: 3 | H7: 2 | I7: -18 | J7: 0 | K7: 2
A8: 12 | B8: luigi | C8: 0 | D8: -1 | E8: 3 | F8: -2 | G8: 2 | H8: 2 | I8: -2 | J8: 3 | K8: 1
A9: 12 | B9: stentaa | C9: 0 | D9: -1 | E9: 3 | F9: 0 | G9: 2 | H9: 0 | I9: -7 | J9: 1 | K9: 2
A10: 12 | B10: leo | C10: 0 | D10: -1 | E10: 3 | F10: -17 | G10: 0 | H10: 3 | I10: -1 | J10: 1 | K10: 3
A11: 12 | B11: cleopatra | C11: 0 | D11: -1 | E11: 3 | F11: -2 | G11: 2 | H11: 1 | I11: 0 | J11: 2 | K11: 1
A12: 11 12 | B12: haha | C12: 0 | D12: -1 | E12: 3 | F12: -2 | G12: 3 | H12: 1 | I12: -3 | J12: 1 | K12: 2
A13: 12 | B13: hikarinorob | C13: 0 | D13: -1 | E13: 3 | F13: -12 | G13: 0 | H13: 3 | I13: -11 | J13: 0 | K13: 2
A14: 11 | B14: brazo | C14: 0 | D14: 0 | E14: 2 | F14: -11 | G14: 0 | H14: 3 | I14: 1 | J14: 2 | K14: 1
A15: 12 | B15: roberta | F15: 0 | G15: 3 | H15: 0 | I15: -11 | J15: -1 | K15: 3
A16: 11 | B16: giosan | C16: 0 | D16: 0 | E16: 2 | F16: -1 | G16: 1 | H16: 1 | I16: -3 | J16: 1 | K16: 1
A17: 11 | B17: hampones | I17: -11 | J17: 0 | K17: 3
A18: 11 | B18: serra008 | C18: 0 | D18: 0 | E18: 3 | F18: -6 | G18: 2 | H18: 1 | I18: 0 | J18: 2 | K18: 1
A19: 11 | B19: dux
A20: 11 | B20: luxor | C20: 0 | D20: 0 | E20: 2
A21: 11 | B21: lakaka | C21: 0 | D21: 0 | E21: 3 | F21: 0 | G21: 3 | H21: 1
A22: 11 | B22: buffxbow | C22: 0 | D22: 0 | E22: 3 | F22: -8 | G22: 0 | H22: 3 | I22: 0 | J22: 2 | K22: 1
A23: 11 | B23: floky | C23: 0 | D23: 0 | E23: 3 | F23: 0 | G23: 3 | H23: 2 | I23: 0 | J23: 2 | K23: 2
A24: 11 | B24: robbycv | C24: 0 | D24: 0 | E24: 3 | F24: 0 | G24: 3 | H24: 1 | I24: 0 | J24: 2 | K24: 1
A25: 11 | B25: juan falco | C25: -3 | D25: 0 | E25: 3 | F25: 0 | G25: 1 | H25: 1 | I25: 0 | J25: 0 | K25: 1
A26: 11 | B26: pigiamone | C26: 0 | D26: 0 | E26: 3 | F26: 4 | G26: 3 | H26: 2
A27: 11 | B27: lokoss | C27: 0 | D27: 1 | E27: 2 | F27: 0 | G27: 3 | H27: 3 | I27: 0 | J27: -1 | K27: 3
A28: 11 | B28: thanos | C28: 0 | D28: 0 | E28: 3 | F28: 1 | G28: 1 | H28: 2 | I28: 1 | J28: 0 | K28: 2
A29: 11 | B29: maikol | C29: 3 | D29: 0 | E29: 3 | F29: 12 | G29: 2 | H29: 1 | I29: 0 | J29: -1 | K29: 3
A30: 11 | B30: dio animale | C30: 0 | D30: 0 | E30: 3 | F30: 0 | G30: -2 | H30: 3 | I30: 0 | J30: -1 | K30: 3
A31: 10 11 | B31: simone | C31: 0 | D31: 0 | E31: 3 | F31: 0 | G31: -1 | H31: 3 | I31: 0 | J31: -1 | K31: 3
B34: attacco basso
B35: attacco pessimo
B36: no attacco
B37: assegnazione forzata

Sheet CWL 2
C1: 1 | F1: 2 | I1: 3 | L1: 4 | O1: 5 | R1: 6 | U1: 7
B2: nome | C2: pos | D2: th | E2: stelle | F2: pos | G2: th | H2: stelle | I2: pos | J2: th | K2: stelle | L2: pos | M2: th | N2: stelle | O2: pos | P2: th | Q2: stelle | R2: pos | S2: th | T2: stelle | U2: pos | V2: th | W2: stelle
A3: 16 | B3: xblade | D3: =avv!A1-A3 | E3: 3 | G3: =avv!B1-A3 | H3: 3 | J3: =avv!C1-A3 | K3: 2 | M3: =avv!D1-A3 | N3: 3 | P3: =avv!E1-A3 | Q3: 3 | S3: =avv!F1-A3 | T3: 3 | V3: =avv!G1-A3 | W3: 3
A4: 15 | B4: marcojk007 | D4: =avv!A2-A4 | E4: 3 | G4: =avv!B2-A4 | H4: 2 | P4: =avv!E2-A4 | Q4: 2 | S4: =avv!F2-A4 | T4: 2 | V4: =avv!G2-A4 | W4: 2
A5: 15 | B5: dado | D5: =avv!A3-A5 | E5: 3 | G5: =avv!B3-A5 | H5: 3 | M5: =avv!D3-A5 | N5: 3 | P5: =avv!E4-A5 | Q5: 3 | S5: =avv!F3-A5 | T5: 1 | V5: =avv!G3-A5 | W5: 3
A6: 13 | B6: chabby | D6: =avv!A4-A6 | E6: 3 | J6: =avv!C4-A6 | K6: 1 | M6: =avv!D4-A6 | N6: 1 | S6: =avv!F4-A6 | T6: 0 | V6: =avv!G4-A6 | W6: 0
A7: 13 | B7: piegian99 | D7: =avv!A7-A7 | E7: 3 | G7: =avv!B10-A7 | H7: 3 | J7: =avv!C7-A7 | K7: 3 | M7: =avv!D5-A7 | N7: 3 | P7: =avv!E5-A7 | Q7: 3 | S7: =avv!F22-A7 | T7: 3 | V7: =avv!G5-A7 | W7: 3
A8: 13 | B8: bigmc | C8: -6 | D8: =avv!A12-A8 | E8: 3 | G8: =avv!B7-A8 | H8: 2 | J8: =avv!C5-A8 | K8: 1 | M8: =avv!D6-A8 | N8: 2 | P8: =avv!E6-A8 | Q8: 2 | S8: =avv!F6-A8 | T8: 1 | V8: =avv!G6-A8 | W8: 1
A9: 13 | B9: luigi01 | S9: =avv!F7-A9 | V9: =avv!G7-A9
A10: 13 | B10: stentaa | D10: =avv!A8-A10 | E10: 2 | G10: =avv!B8-A10 | H10: 1 | J10: =avv!C8-A10 | K10: 3 | M10: =avv!D8-A10 | N10: 2 | P10: =avv!E10-A10 | Q10: 3 | S10: =avv!F8-A10 | T10: 2 | V10: =avv!G8-A10 | W10: 2
A11: 13 | B11: luigi | D11: =avv!A9-A11 | E11: 3 | G11: =avv!B9-A11 | H11: 2 | J11: =avv!C9-A11 | K11: 2 | M11: =avv!D9-A11 | N11: 1 | P11: =avv!E9-A11 | Q11: 3 | S11: =avv!F9-A11 | T11: 2 | V11: =avv!G9-A11 | W11: 3
A12: 13 | B12: brazo | D12: =avv!A10-A12 | E12: 2 | M12: =avv!D28-A12 | N12: 3 | P12: =avv!E10-A12 | Q12: 2 | S12: =avv!F24-A12 | T12: 3 | V12: =avv!G10-A12
A13: 12 | B13: cleopatra | D13: =avv!A20-A13 | E13: 3 | G13: =avv!B11-A13 | H13: 2 | J13: =avv!C11-A13 | K13: 1 | M13: =avv!D11-A13 | N13: 2 | P13: =avv!E12-A13 | Q13: 3 | S13: =avv!F11-A13 | T13: 2 | V13: =avv!G11-A13 | W13: 2
A14: 12 | B14: hikarinorob | D14: =avv!A6-A14 | E14: 2 | G14: =avv!B12-A14 | H14: 2 | J14: =avv!C12-A14 | K14: 3 | M14: =avv!D12-A14 | N14: 2 | P14: =avv!E13-A14 | Q14: 3 | S14: =avv!F12-A14 | T14: 2 | V14: =avv!G12-A14 | W14: 3
A15: 12 | B15: leo | D15: =avv!A13-A15 | E15: 3 | G15: =avv!B13-A15 | H15: 3 | J15: =avv!C13-A15 | K15: 2 | M15: =avv!D13-A15 | N15: 2 | P15: =avv!E17-A15 | Q15: 3 | S15: =avv!F13-A15 | T15: 1 | V15: =avv!G13-A15 | W15: 2
A16: 13 | B16: giosan | D16: =avv!A15-A16 | E16: 3 | G16: =avv!B14-A16 | H16: 3 | J16: =avv!C15-A16 | K16: 1 | M16: =avv!D14-A16 | N16: 1 | P16: =avv!E14-A16 | Q16: 2 | S16: =avv!F14-A16 | T16: 2 | V16: =avv!G14-A16 | W16: 1
A17: 12 | B17: haha | D17: =avv!A14-A17 | E17: 3 | G17: =avv!B16-A17 | H17: 3 | J17: =avv!C14-A17 | K17: 3 | M17: =avv!D15-A17 | N17: 2 | P17: =avv!E15-A17 | Q17: 3 | S17: =avv!F15-A17 | T17: 2 | V17: =avv!G15-A17 | W17: 3
A18: 12 | B18: zombra | D18: =avv!A16-A18 | E18: 3 | G18: =avv!B17-A18 | H18: 3 | J18: =avv!C16-A18 | K18: 3 | M18: =avv!D16-A18 | N18: 2 | P18: =avv!E16-A18 | Q18: 3 | S18: =avv!F16-A18 | T18: 1 | V18: =avv!G16-A18 | W18: 1
A19: 12 | B19: roberta | P19: =avv!E28-A19 | Q19: 1 | S19: =avv!F28-A19 | T19: 1 | V19: =avv!G17-A19 | W19: 1
A20: 12 | B20: floky | D20: =avv!A17-A20 | E20: 3 | G20: =avv!B18-A20 | H20: 1 | J20: =avv!C17-A20 | K20: 3 | M20: =avv!D17-A20 | N20: 2 | P20: =avv!E17-A20 | Q20: 3 | S20: =avv!F17-A20 | T20: 1 | V20: =avv!G18-A20 | W20: 2
A21: 12 | B21: buff-x-bow | J21: =avv!C19-A21 | K21: 2 | M21: =avv!D19-A21 | N21: 3 | P21: =avv!E19-A21 | Q21: 3 | S21: =avv!F19-A21 | T21: 3 | V21: =avv!G19-A21 | W21: 2
A22: 12 | B22: serra008 | D22: =avv!A18-A22 | E22: 3 | G22: =avv!B19-A22 | H22: 3 | J22: =avv!C18-A22 | K22: 3 | M22: =avv!D18-A22 | N22: 1 | P22: =avv!E18-A22 | Q22: 3 | S22: =avv!F18-A22 | T22: 3 | V22: =avv!G20-A22 | W22: 1
A23: 12 | B23: pigiamone99 | D23: =avv!A19-A23 | E23: 3 | G23: =avv!B20-A23 | H23: 3 | J23: =avv!C20-A23 | K23: 3 | M23: =avv!D20-A23 | N23: 3 | P23: =avv!E22-A23 | Q23: 3 | S23: =avv!F20-A23 | T23: 3 | V23: =avv!G21-A23 | W23: 3
A24: 12 | B24: dux | M24: =avv!D22-A24 | N24: 3 | S24: =avv!F22-A24 | V24: =avv!G22-A24 | W24: 3
A25: 12 | B25: d 011 | D25: =avv!A29-A25 | E25: 3 | G25: =avv!B27-A25 | H25: 2 | J25: =avv!C21-A25 | K25: 3 | P25: =avv!E22-A25 | Q25: 0 | S25: =avv!F21-A25 | V25: =avv!G23-A25
A26: 12 | B26: luxor | D26: =avv!A22-A26 | E26: 3 | G26: =avv!B23-A26 | H26: 3 | M26: =avv!D23-A26 | N26: 2 | P26: =avv!E23-A26 | Q26: 3 | S26: =avv!F23-A26 | V26: =avv!G24-A26 | W26: 2
A27: 12 | B27: sono io lakaka | D27: =avv!A23-A27 | E27: 3 | G27: =avv!B24-A27 | H27: 3 | J27: =avv!C24-A27 | K27: 3 | P27: =avv!E25-A27 | Q27: 3 | S27: =avv!F24-A27 | T27: 3 | V27: =avv!G25-A27 | W27: 1
A28: 12 | B28: thanos | D28: =avv!A24-A28 | E28: 3 | G28: =avv!B26-A28 | H28: 3 | J28: =avv!C25-A28 | K28: 3 | M28: =avv!D25-A28 | N28: 3 | P28: =avv!E25-A28 | Q28: 3 | S28: =avv!F25-A28 | T28: 3 | V28: =avv!G26-A28 | W28: 3
A29: 12 | B29: sidcu | C29: 18+ pos | D29: =avv!A11-A29 | E29: 3 | G29: =avv!B30-A29 | H29: 3 | J29: =avv!C30-A29 | K29: 3 | M29: =avv!D26-A29 | N29: 1 | P29: =avv!E27-A29 | Q29: 3 | S29: =avv!F26-A29 | T29: 3 | V29: =avv!G27-A29 | W29: 3
A30: 12 | B30: robbycv | D30: =avv!A25-A30 | E30: 3 | F30: 1 | G30: =avv!B25-A30 | H30: 3 | J30: =avv!C26-A30 | K30: 3 | M30: =avv!D27-A30 | N30: 3 | P30: =avv!E28-A30 | Q30: 3 | S30: =avv!F27-A30 | T30: 3 | V30: =avv!G28-A30 | W30: 1
A31: 12 | B31: simone | D31: =avv!A28-A31 | E31: 3 | G31: =avv!B28-A31 | H31: 3 | J31: =avv!C28-A31 | K31: 3 | M31: =avv!D29-A31 | N31: 3 | P31: =avv!E29-A31 | Q31: 3 | S31: =avv!F29-A31 | T31: 3 | V31: =avv!G29-A31 | W31: 2
A32: 12 | B32: kakko garau | D32: =avv!A27-A32 | E32: 3 | G32: =avv!B29-A32 | H32: 3 | J32: =avv!C29-A32 | K32: 3 | S32: =avv!F30-A32 | T32: 3 | V32: =avv!G30-A32 | W32: 3
A34: 12 | B34: serena | D34: =avv!A30-A34 | E34: 3 | P34: =avv!E32-A34 | S34: =avv!F32-A34 | V34: =avv!G32-A34
A35: 13 | B35: di gio
A36: 12 | B36: heloo
B38: attacco basso
B39: attacco pessimo
B40: no attacco
B41: attacco ok
B42: ottimo attacco
...

Sheet CWL 3
C1: 1 | F1: 2 | I1: 3 | L1: 4 | O1: 5 | R1: 6 | U1: 7
B2: nome | C2: pos | D2: th | E2: stelle | F2: pos | G2: th | H2: stelle | I2: pos | J2: th | K2: stelle | L2: pos | M2: th | N2: stelle | O2: pos | P2: th | Q2: stelle | R2: pos | S2: th | T2: stelle | U2: pos | V2: th | W2: stelle
A3: 16 | B3: xbladze | D3: 0 | E3: 2 | G3: 2 | H3: 1 | M3: -1 | N3: 2 | P3: 2 | Q3: 2 | S3: 0 | T3: 2 | V3: 1 | W3: 1
A4: 15 | B4: dado | D4: 1 | E4: 2 | G4: 1 | H4: 1 | M4: 0 | N4: 3 | P4: 3 | Q4: 2 | S4: -1 | T4: 2 | V4: 1 | W4: 2
A5: 14 | B5: Stentaaa | D5: 0 | E5: 2 | G5: 2 | H5: 2 | J5: 1 | K5: 3 | M5: 2 | N5: 1 | P5: 3 | Q5: 0 | S5: 0 | T5: 3 | V5: 0 | W5: 3
A6: 14 | B6: BigMc23 | D6: 0 | E6: 2 | G6: 1 | H6: 1 | J6: 1 | K6: 2 | M6: 1 | N6: 0 | P6: 2 | Q6: 1 | S6: -1 | T6: 2 | V6: 0 | W6: 3
A7: 14 | B7: piegian99 | D7: 0 | E7: 3 | G7: 1 | H7: 2 | J7: 0 | K7: 3 | M7: 0 | N7: 3 | P7: 0 | Q7: 3 | S7: -1 | T7: 3 | V7: 0 | W7: 3
A8: 13 | B8: GiornoBrando | D8: 0 | E8: 3 | G8: 1 | H8: 1 | J8: 1 | K8: 1 | M8: 1 | N8: 2 | P8: 3 | Q8: 1 | S8: 0 | T8: 3 | V8: 0 | W8: 3
A9: 13 | B9: Valh | D9: 0 | E9: 3 | G9: 0 | H9: 3 | J9: 1 | K9: 3 | M9: 1 | N9: 2 | P9: 2 | Q9: 2 | S9: -1 | T9: 3 | V9: -1 | W9: 1
A10: 13 | B10: Queen of Shadow | D10: 0 | E10: 3 | G10: 0 | H10: 3 | J10: 1 | K10: 2 | M10: 1 | N10: 1 | P10: 3 | Q10: 2 | S10: 0 | T10: 3 | V10: 0 | W10: 3
A11: 13 | B11: Luigi | D11: 0 | E11: 3 | G11: 0 | H11: 3 | J11: 1 | K11: 2 | M11: 1 | N11: 3 | P11: 2 | Q11: 1 | S11: 0 | T11: 3 | V11: 0 | W11: 3
A12: 13 | B12: MASCHI | G12: -1 | H12: 3 | J12: 0 | K12: 1 | M12: 1 | N12: 1 | P12: 2 | Q12: 0 | S12: -2 | T12: 3 | V12: 0 | W12: 2
A13: 13 | B13: ¥CATA¥ | D13: 0 | E13: 3 | S13: 0 | T13: 3 | V13: 0 | W13: 3
A14: 13 | B14: xNullx | D14: 0 | E14: 3 | G14: -1 | H14: 3 | J14: 1 | K14: 2 | M14: 1 | N14: 2 | P14: 1 | Q14: 3 | S14: 0 | T14: 3 | V14: 0 | W14: 3
A15: 13 | B15: HikariNoRob | D15: 0 | E15: 3 | G15: -1 | H15: 3 | J15: 1 | K15: 2 | M15: 1 | N15: 3 | P15: 0 | Q15: 3 | S15: -1 | T15: 3 | V15: -1 | W15: 3
A16: 13 | B16: leo | D16: 0 | E16: 3 | G16: -1 | H16: 3 | J16: 1 | K16: 2 | P16: 2 | Q16: 1 | S16: -2 | T16: 3 | V16: 0 | W16: 3
A17: 13 | B17: gionny | D17: -1 | E17: 3 | G17: -1 | H17: 2 | J17: 1 | K17: 1 | M17: 0 | N17: 2 | P17: 1 | Q17: 1 | S17: -2 | T17: 3 | V17: -1 | W17: 2
A18: 13 | B18: giosan | D18: -1 | E18: 2 | G18: -1 | H18: 3 | J18: 0 | K18: 2 | M18: 0 | N18: 2 | P18: 0 | Q18: 1 | S18: -2 | T18: 3 | V18: -1 | W18: 2
A19: 13 | B19: Floky23 | D19: -1 | E19: 3 | G19: -1 | H19: 3 | J19: 0 | K19: 3 | M19: 0 | N19: 2 | P19: 1 | Q19: 3 | S19: -2 | T19: 3 | V19: -1 | W19: 3
A20: 12 | B20: haha | D20: 0 | E20: 3 | G20: -1 | H20: 3 | J20: 0 | K20: 1 | M20: 1 | N20: 3 | P20: 1 | Q20: 1 | S20: -2 | T20: 3 | V20: -1 | W20: 3
A21: 13 | B21: ER DANDI 1927 | J21: 1 | K21: 2 | P21: 1 | Q21: 2 | S21: -1 | T21: 3 | V21: 0 | W21: 2
A22: 12 | B22: serra008 | D22: 0 | E22: 3 | G22: -1 | H22: 3 | J22: 1 | K22: 3 | M22: 1 | N22: 1 | P22: 1 | Q22: 2 | S22: -2 | T22: 3 | V22: -1 | W22: 3
A23: 12 | B23: pigiamone99 | D23: 0 | E23: 3 | G23: -1 | H23: 3 | J23: 0 | K23: 3 | M23: 1 | N23: 1 | P23: 1 | Q23: 2 | S23: -2 | T23: 3 | V23: 0 | W23: 2
A24: 12 | B24: SubOhm | D24: 0 | E24: 2 | G24: -1 | H24: 3 | J24: 0 | K24: 3 | M24: 1 | N24: 1 | P24: 1 | Q24: 1 | S24: -3 | T24: 3 | V24: 0 | W24: 3
A25: 12 | B25: Luxor | D25: 0 | E25: 2 | G25: -1 | H25: 3 | J25: 0 | K25: 3 | M25: 1 | N25: 1 | P25: 1 | Q25: 2 | S25: -3 | T25: 3 | V25: 0 | W25: 3
A26: 12 | B26: th4nos | D26: 0 | E26: 3 | G26: -1 | H26: 3 | J26: 0 | K26: 3 | M26: 1 | N26: 2 | P26: 1 | Q26: 1 | S26: -3 | T26: 3 | V26: 0 | W26: 3
A27: 12 | B27: sono io lakaka | D27: 0 | E27: 3 | G27: -1 | H27: 3 | J27: 0 | K27: 3 | M27: 0 | N27: 2 | P27: 0 | Q27: 2 | R27: !!!!!!! | S27: 0 | T27: 1 | V27: -1 | W27: 3
A28: 12 | B28: maikol_lix | D28: 0 | E28: 3 | G28: -2 | H28: 3 | J28: 0 | K28: 3 | M28: 1 | N28: 3 | P28: 1 | Q28: 1 | S28: -4 | T28: 3 | V28: 0 | W28: 3
A29: 12 | B29: Simone | D29: -1 | E29: 3 | G29: -2 | H29: 3 | J29: 0 | K29: 3 | M29: 0 | N29: 2 | P29: 0 | Q29: 3 | S29: -3 | T29: 3 | V29: 0 | W29: 3
A30: 12 | B30: sidcujs | P30: 0 | Q30: 3 | S30: -4 | T30: 3
A31: 12 | B31: RobbyCV | D31: -3 | E31: 3 | G31: -3 | H31: 3 | J31: 0 | K31: 3 | P31: -1 | Q31: 3 | S31: -4 | T31: 3 | V31: 0 | W31: 2
A32: 10 | B32: ajejebrazorf | G32: -2 | H32: 3 | J32: 0 | K32: 3 | M32: 1 | N32: 2 | P32: 0 | Q32: 3 | S32: -4 | T32: 3 | V32: -1 | W32: 2
A35: 13 | B35: R1cky_boffo
A36: 13 | B36: Brazo
A37: 13 | B37: Favij
A38: 13 | B38: Essenc3_kin4
A39: 13 | B39: Zine
A40: 12 | B40: Roberta
A41: 13 | B41: ggfgd
A42: 13 | B42: zombra
...

Sheet CWL 4
C1: 1 | F1: 2 | I1: 3 | L1: 4 | O1: 5 | R1: 6 | U1: 7
B2: nome | C2: pos | D2: th | E2: stelle | F2: pos | G2: th | H2: stelle | I2: pos | J2: th | K2: stelle | L2: pos | M2: th | N2: stelle | O2: pos | P2: th | Q2: stelle | R2: pos | S2: th | T2: stelle | U2: pos | V2: th | W2: stelle
A3: 17 | B3: xbladze | D3: 1 | E3: 2 | G3: 1 | H3: 3 | J3: -1 | K3: 3 | M3: 0 | N3: 2 | P3: 1 | Q3: 2 | S3: 1 | T3: 3 | V3: -2 | W3: 3 | X3: x
A4: 15 | B4: dado | D4: 1 | E4: 2 | F4: -1 | G4: 0 | H4: 3 | J4: 1 | K4: 2 | M4: 2 | N4: 2 | P4: 1 | Q4: 3 | S4: 1 | T4: 2 | V4: -1 | W4: 3 | X4: x
A5: 14 | B5: zordan | D5: 1 | E5: 3 | G5: 1 | H5: 3 | J5: 2 | K5: 1 | M5: 3 | N5: 2 | P5: 1 | Q5: 2 | S5: 1 | T5: 2 | V5: 0 | W5: 3 | X5: x
A6: 14 | B6: PIPPII | D6: 1 | E6: 2 | G6: 1 | H6: 2 | J6: 0 | K6: 1 | M6: 2 | N6: 1 | P6: 0 | Q6: 2 | S6: 0 | T6: 2 | V6: 0 | W6: 3 | X6: n
A7: 14 | B7: Stentaaa | D7: 1 | E7: 2 | G7: -1 | H7: 3 | J7: 0 | K7: 1 | M7: 2 | N7: 2 | P7: 0 | Q7: 2 | S7: -1 | T7: 3 | V7: -1 | W7: 3 | X7: n
A8: 14 | B8: piegian99 | D8: 0 | E8: 3 | G8: -1 | H8: 3 | J8: 1 | K8: 2 | M8: 2 | N8: 2 | P8: 0 | Q8: 3 | S8: 1 | T8: 3 | V8: 0 | W8: 3 | X8: x
A9: 14 | B9: Luigi | D9: 0 | E9: 3 | G9: -1 | H9: 3 | J9: 0 | K9: 2 | M9: 1 | N9: 2 | P9: 0 | Q9: 3 | S9: -1 | T9: 3 | V9: -1 | W9: 3 | X9: x
A10: 14 | B10: BigMc23 | D10: 0 | E10: 2 | G10: -1 | H10: 2 | J10: 0 | K10: 2 | M10: 0 | N10: 2 | P10: 0 | Q10: 2 | S10: -1 | T10: 3 | V10: -1 | W10: 3 | X10: n
A11: 14 | B11: Kle | D11: -1 | E11: 3 | G11: -1 | H11: 3 | J11: 0 | K11: 3 | M11: 0 | N11: 1 | P11: 0 | Q11: 3 | S11: -1 | T11: 3 | V11: -1 | W11: 3 | X11: n
A12: 14 | B12: GiornoBrando | D12: 0 | E12: 3 | G12: -1 | H12: 3 | J12: 0 | K12: 2 | M12: -2 | N12: 3 | P12: -1 | Q12: 3 | S12: -1 | T12: 3 | V12: -1 | W12: 3 | X12: n
A13: 14 | B13: LucFir3 | D13: -1 | E13: 0 | G13: -1 | H13: 1 | J13: 0 | K13: 2 | P13: -1 | Q13: 3 | S13: -1 | T13: 3 | V13: -1 | W13: 3 | X13: n
A14: 13 | B14: revolver | D14: 0 | E14: 3 | G14: 0 | H14: 3 | J14: 1 | K14: 3 | M14: -1 | N14: 3 | P14: 0 | Q14: 3 | S14: 0 | T14: 3 | V14: -1 | W14: 3 | X14: x
A15: 14 | B15: ¥CATA¥ | D15: -1 | E15: 3 | J15: 0 | K15: 2 | P15: 0 | Q15: 3 | V15: -1 | W15: 3 | X15: n
A16: 13 | B16: HikariNoRob | D16: -1 | E16: 3 | G16: -1 | H16: 3 | J16: 1 | K16: 3 | M16: -1 | N16: 3 | P16: 0 | Q16: 3 | S16: 0 | T16: 3 | V16: -1 | W16: 3 | X16: x
A17: 13 | B17: leo | D17: -1 | E17: 3 | G17: -1 | H17: 3 | J17: -1 | K17: 3 | M17: -1 | N17: 3 | P17: -1 | Q17: 3 | S17: -1 | T17: 3 | V17: -1 | W17: 3
A18: 13 | B18: haha | D18: -1 | E18: 3 | G18: -1 | H18: 3 | J18: -1 | K18: 3 | M18: -1 | N18: 3 | P18: -1 | Q18: 3 | S18: -1 | T18: 3 | V18: -1 | W18: 3
A19: 13 | B19: pigiamone99 | D19: -1 | E19: 3 | G19: -1 | H19: 3 | J19: -1 | K19: 3 | M19: -1 | N19: 3 | P19: -1 | Q19: 3 | S19: 0 | T19: 3 | V19: -1 | W19: 3 | X19: n
A20: 13 | B20: andriu07 | D20: -1 | E20: 3 | G20: -1 | H20: 3 | J20: -1 | K20: 3 | M20: -1 | N20: 3 | P20: -1 | Q20: 3 | S20: -1 | T20: 2 | V20: -1 | W20: 3 | X20: n
A21: 13 | B21: serra008 | D21: -1 | E21: 3 | G21: -1 | H21: 3 | J21: -1 | K21: 3 | M21: -1 | N21: 3 | P21: -1 | Q21: 3 | S21: -1 | T21: 3 | V21: -1 | W21: 3
A22: 13 | B22: Luxor | D22: -1 | E22: 3 | G22: -1 | H22: 3 | J22: -1 | K22: 3 | M22: -1 | N22: 3 | P22: -1 | Q22: 3 | S22: -1 | T22: 3 | V22: -1 | W22: 3
A23: 13 | B23: th4nos | C23: 12 | D23: 0 | E23: 3 | G23: -1 | H23: 3 | J23: 0 | K23: 3 | M23: -1 | N23: 3 | P23: -1 | Q23: 3 | S23: -1 | T23: 3 | V23: -1 | W23: 3
A24: 13 | B24: ER DANDI 1927 | D24: -1 | E24: 3 | G24: -1 | H24: 3 | J24: -2 | K24: 3 | M24: -2 | N24: 3 | S24: -1 | T24: 3 | V24: -1 | W24: 3
A25: 13 | B25: Floky23 | D25: -1 | E25: 3 | G25: -1 | H25: 3 | J25: -2 | K25: 3 | M25: -2 | N25: 3 | P25: -1 | Q25: 3 | S25: -1 | T25: 3 | V25: -1 | W25: 3
A26: 12 | B26: buff-x-bow | D26: 0 | E26: 3 | G26: 0 | H26: 3 | J26: -2 | K26: 3 | M26: -2 | N26: 3 | P26: 0 | Q26: 3 | S26: 0 | T26: 3 | V26: 0 | W26: 3
A27: 12 | B27: maikol_lix | D27: -1 | E27: 3 | G27: 0 | H27: 3 | J27: -2 | K27: 3 | M27: -3 | N27: 3 | P27: -1 | Q27: 3 | S27: 0 | T27: 3 | V27: 0 | W27: 3
A28: 12 | B28: Simone | D28: -1 | E28: 3 | G28: -1 | H28: 3 | J28: -2 | K28: 3 | M28: -3 | N28: 3 | P28: -1 | Q28: 3 | S28: 0 | T28: 3 | V28: 0 | W28: 2 | X28: n
A29: 12 | B29: RobbyCV | D29: -4 | E29: 3 | G29: -1 | H29: 3 | J29: -2 | K29: 3 | M29: -3 | N29: 3 | P29: -2 | Q29: 3 | S29: -1 | T29: 3 | V29: 0 | W29: 3
A30: 11 | B30: ajejebrazorf | G30: -2 | H30: 3 | S30: -1 | T30: 3 | V30: 0 | W30: 3 | X30: n
A31: 12 | B31: favretto | G31: -2 | H31: 3 | J31: -4 | K31: 3 | M31: -4 | N31: 3 | P31: -4 | Q31: 3 | S31: -1 | T31: 3 | V31: 1 | W31: 1 | X31: n
A34: 13 | B34: francesco
A35: 14 | B35: gionny
A36: 14 | B36: gionny
A37: 13 | B37: Fryck | C37: -12 | D37: -2 | E37: 3 | J37: -2 | K37: 1 | M37: -1 | N37: 3 | P37: -2 | Q37: 3 | R37: -16 | S37: -2 | T37: 3
A38: 13 | B38: IL MAGO NERO
B40: attacco basso
B41: attacco brutto
B42: no attacco
B43: ottimo attacco
...

Sheet CWL 5
C1: 1 | F1: 2 | I1: 3 | L1: 4 | O1: 5 | R1: 6 | U1: 7
B2: nome | C2: pos | D2: th | E2: stelle | F2: pos | G2: th | H2: stelle | I2: pos | J2: th | K2: stelle | L2: pos | M2: th | N2: stelle | O2: pos | P2: th | Q2: stelle | R2: pos | S2: th | T2: stelle | U2: pos | V2: th | W2: stelle
A3: 17 | B3: xbladze | D3: X | J3: x | P3: x | V3: x
A4: 16 | B4: dado | M4: x | P4: x | S4: x | V4: x
A5: 15 | B5: PIPPII | D5: X | G5: X | J5: x | M5: x | P5: x | S5: x | V5: x
A6: 15 | B6: Luigi | D6: X | G6: X | J6: x | M6: x | P6: x | S6: x | V6: x
A7: 15 | B7: piegian99 | D7: X | G7: X | J7: x | M7: x | P7: x | S7: x | V7: x | AB7: Big giurz08
A8: 15 | B8: Stentaaa | D8: X | G8: X | J8: x | M8: x | S8: x | V8: x
A9: 15 | B9: GiornoBrando | D9: X | G9: X | M9: x | P9: x | S9: x | V9: x
A11: 15 | B11: BigMc23 | D11: X | J11: x | M11: x | P11: x | S11: x | V11: x
A12: 14 | B12: Revolver | D12: X | G12: X | J12: x | M12: x | P12: x | S12: x | V12: x
A13: 14 | B13: Kle | D13: X | J13: x | P13: x | S13: x | V13: x
A14: 14 | B14: leo | D14: X | G14: X | J14: x | M14: x | P14: x | S14: x | V14: x
A15: 14 | B15: MIRIAM MIRIAM | D15: X | J15: x | P15: x | S15: x | V15: x
A16: 14 | B16: haha | D16: X | G16: X | J16: x | M16: x | P16: x | S16: x | V16: x
A17: 14 | B17: pigiamone99 | D17: X | G17: X | J17: x | M17: x | P17: x | S17: x | V17: x
A18: 14 | B18: Amazonie | D18: X | G18: X | J18: x | M18: x | P18: x | S18: x | V18: x
A21: 14 | B21: Luca | G21: X | J21: x | M21: x | P21: x | S21: x | V21: x
A22: 13 | B22: buff-x-bow | D22: X | G22: X | J22: x | M22: x | P22: x | S22: x | V22: x
A23: 13 | B23: Juri | D23: X | G23: X | J23: x | M23: x | P23: x | S23: x | V23: x
A24: 13 | B24: TinoGiusa | G24: X | J24: x | M24: x | P24: x | S24: x | V24: x
A25: 13 | B25: Floky23 | D25: X | G25: X | J25: x | M25: x | P25: x | S25: x | V25: x
A26: 13 | B26: Simone | D26: X | P26: x | S26: x | V26: x
A27: 13 | B27: Edoardo9 | G27: X | J27: x | M27: x | P27: x | S27: x | V27: x
A30: 13 | B30: maikol_lix
A32: 12 | B32: RobbyCV | D32: X | G32: X | J32: x | M32: x | P32: x | S32: x | V32: x
A34: 13 | B34: EMA ALBA003
A35: 14 | B35: gionny
A36: 14 | B36: gionny
A37: 13 | B37: Fryck | C37: -12 | D37: -2 | E37: 3 | J37: -2 | K37: 1 | M37: -1 | N37: 3 | P37: -2 | Q37: 3 | R37: -16 | S37: -2 | T37: 3
A38: 13 | B38: IL MAGO NERO
B40: attacco basso
B41: attacco brutto
B42: no attacco
B43: ottimo attacco
B44: ottimo attacco
B45: attacco meh
B46: NO SONDAGGIO
B47: inserito dopo

Sheet CWL 6
C1: 1 | F1: 2 | I1: 3 | L1: 4 | O1: 5 | R1: 6 | U1: 7
B2: nome | C2: pos | D2: th | E2: stelle | F2: pos | G2: th | H2: stelle | I2: pos | J2: th | K2: stelle | L2: pos | M2: th | N2: stelle | O2: pos | P2: th | Q2: stelle | R2: pos | S2: th | T2: stelle | U2: pos | V2: th | W2: stelle
A3: 17 | B3: xbladze | G3: 0 | H3: 1 | J3: 1 | K3: 1 | N3: 3 | P3: 1 | Q3: 3 | S3: -1 | T3: 3
A4: 16 | B4: dado | D4: 1 | E4: 2 | G4: N | K4: 2 | N4: 3 | S4: 0 | T4: 2
A5: 15 | B5: PIPPII | D5: 2 | E5: 3 | G5: 2 | H5: 1 | J5: N | N5: 2 | S5: 0 | T5: 3 | V5: 1 | W5: 2
A6: 15 | B6: Luigi | D6: 2 | E6: 3 | G6: 0 | H6: 3 | J6: 1 | K6: 3 | N6: 3 | P6: 3 | Q6: 2 | S6: 0 | T6: 3
A7: 15 | B7: piegian99 | D7: -1 | E7: 3 | G7: 0 | H7: 3 | J7: 0 | K7: 3 | N7: 3 | P7: 2 | Q7: 3 | S7: 0 | T7: 3 | V7: 0 | W7: 3
A8: 15 | B8: Stentaaa | D8: -1 | E8: 3 | G8: -1 | H8: 3 | J8: 0 | K8: 2 | N8: 3 | P8: 1 | Q8: 2 | S8: 0 | T8: 2 | V8: -1 | W8: 3
A9: 15 | B9: GiornoBrando | D9: 0 | E9: 3 | G9: -2 | H9: 3 | J9: 0 | K9: 2 | N9: 3 | P9: 1 | Q9: 1 | S9: 0 | T9: 1 | V9: -1 | W9: 3
A10: 15 | B10: xNullx | D10: -1 | E10: 3 | G10: -2 | H10: 3 | J10: 0 | K10: 3 | N10: 3 | P10: 1 | Q10: 3 | S10: 0 | T10: 3 | V10: -2 | W10: 3
A11: 15 | B11: BigMc23 | D11: -1 | E11: 2 | G11: -2 | H11: 3 | J11: 0 | K11: 3 | N11: 3 | P11: 0 | Q11: 2 | S11: 0 | T11: 2
A12: 14 | B12: Revolver | D12: 0 | E12: 3 | G12: -1 | H12: 3 | J12: 0 | K12: 3 | N12: 3 | P12: 0 | Q12: 3 | S12: 1 | T12: 3 | V12: -1 | W12: 3
A13: 14 | B13: Kle | D13: 0 | E13: 3 | G13: N | J13: 0 | K13: 2 | N13: 3 | V13: -1 | W13: 3
A14: 14 | B14: leo | D14: 0 | E14: 3 | G14: -1 | H14: 3 | J14: 0 | K14: 3 | N14: 3 | P14: 0 | Q14: 3 | S14: 1 | T14: 2 | V14: -1 | W14: 3
A15: 14 | B15: MIRIAM MIRIAM | D15: 0 | E15: 3 | G15: -1 | H15: 3 | J15: N | M15: N
A16: 14 | B16: haha | D16: 0 | E16: 3 | G16: -1 | H16: 3 | J16: 0 | K16: 3 | N16: 3 | P16: 0 | Q16: 3 | S16: 0 | T16: 3 | V16: -1 | W16: 3
A17: 14 | B17: pigiamone99 | D17: 0 | E17: 3 | G17: -1 | H17: 3 | J17: 0 | K17: 3 | N17: 3 | P17: 0 | Q17: 3 | S17: 0 | T17: 3 | V17: -1 | W17: 3
A18: 14 | B18: Amazonie | D18: -1 | E18: 3 | G18: -1 | H18: 3 | J18: 0 | K18: 3 | N18: 3 | P18: 0 | Q18: 3 | S18: 0 | T18: 3 | V18: -1 | W18: 3
A19: 14 | B19: Anto | D19: -1 | E19: 1 | G19: -1 | H19: 3 | J19: 0 | K19: 1 | N19: 3 | P19: 0 | Q19: 3 | S19: 0 | T19: 1 | V19: -1 | W19: 3
A20: 14 | B20: Anonymus | D20: 0 | E20: 3 | G20: -1 | H20: 3 | J20: 0 | K20: 3 | N20: 3 | P20: -1 | Q20: 3 | S20: 0 | T20: 3
A21: 14 | B21: Luca | D21: -1 | E21: 3 | G21: -1 | H21: 3 | J21: -1 | K21: 3 | N21: 3 | P21: -1 | Q21: 3 | S21: 0 | T21: 3 | V21: -1 | W21: 3
A22: 13 | B22: buff-x-bow | D22: 0 | E22: 3 | G22: -1 | H22: 3 | K22: 3 | N22: 3 | P22: 0 | Q22: 3 | S22: 1 | T22: 3 | V22: 0 | W22: 3
A23: 13 | B23: Juri | D23: N | G23: -1 | H23: 3 | K23: 3 | P23: 0 | Q23: 3 | S23: 1 | T23: 2 | V23: 0 | W23: 3
A24: 13 | B24: TinoGiusa | D24: 0 | E24: 3 | G24: -1 | H24: 3 | J24: -1 | K24: 3 | N24: 3 | P24: 0 | Q24: 3 | S24: 0 | T24: 3 | V24: 0 | W24: 3
A25: 13 | B25: Floky23 | D25: 0 | E25: 3 | G25: -1 | H25: 3 | J25: N | N25: 3 | P25: 0 | Q25: 3 | S25: 0 | T25: 3 | V25: 0 | W25: 3
A26: 13 | B26: Simone | D26: 0 | E26: 3 | G26: -1 | H26: 3 | J26: -1 | K26: 3 | N26: 3 | P26: 0 | Q26: 3 | S26: 0 | T26: 3 | V26: 0 | W26: 3
A27: 13 | B27: Edoardo9 | D27: 0 | E27: 3 | G27: -3 | H27: 3 | J27: -1 | K27: 3 | N27: 3 | P27: 0 | Q27: 3 | S27: 0 | T27: 3 | V27: 0 | W27: 3
A28: 13 | B28: El sushino | G28: -1 | H28: 3 | J28: -1 | K28: 3 | N28: 3 | P28: 0 | Q28: 3 | S28: 0 | T28: 3 | V28: 0 | W28: 3
A29: 13 | B29: Francesco10 | D29: -2 | E29: 3 | G29: -3 | H29: 3 | J29: -1 | K29: 3 | N29: 3 | P29: -1 | Q29: 3 | S29: 0 | T29: 3 | V29: 0 | W29: 3
A30: 13 | B30: maikol_lix | D30: -2 | E30: 3 | G30: -3 | H30: 3 | J30: -1 | K30: 3 | N30: 3 | P30: -2 | Q30: 3 | S30: 0 | T30: 3 | V30: 0 | W30: 3
S31: -1 | T31: 3
A32: 12 | B32: RobbyCV | D32: N | G32: -4 | H32: 3 | J32: -2 | K32: 3 | N32: 3 | P32: -3 | Q32: 3 | S32: -1 | T32: 3 | V32: 0 | W32: 3
A34: 13 | B34: EMA ALBA003
A35: 14 | B35: gionny
A36: 14 | B36: gionny
A37: 13 | B37: Fryck | C37: -12 | D37: -2 | E37: 3 | J37: -2 | K37: 1 | M37: -1 | N37: 3 | P37: -2 | Q37: 3 | R37: -16 | S37: -2 | T37: 3
A38: 13 | B38: IL MAGO NERO
B40: attacco basso
B41: attacco brutto
B42: no attacco
...

Sheet CWL 7
C1: 1 | F1: 2 | I1: 3 | L1: 4 | O1: 5 | R1: 6 | U1: 7
B2: nome | C2: pos | D2: th | E2: stelle | F2: pos | G2: th | H2: stelle | I2: pos | J2: th | K2: stelle | L2: pos | M2: th | N2: stelle | O2: pos | P2: th | Q2: stelle | R2: pos | S2: th | T2: stelle | U2: pos | V2: th | W2: stelle
A3: 17 | B3: xbladze
A4: 16 | B4: dado
A5: 16 | B5: xNullx | E5: 3
A6: 15 | B6: piegian99 | E6: 3
A7: 15 | B7: Luigi | E7: 3
A8: 15 | B8: GiornoBrando | E8: 3
A9: 15 | B9: Stentaaa
A10: 15 | B10: BigMc23
A11: 15 | B11: maragno
A12: 15 | B12: ZAIZERS
A13: 14 | B13: pigiamone99
A14: 14 | B14: roberto
A15: 14 | B15: Akemi
A16: 14 | B16: haha | E16: 3
A17: 14 | B17: Subhom
A18: 14 | B18: Anonymus | E18: 3
A19: 14 | B19: Anto
A20: 14 | B20: Amazonie
A21: 13 | B21: Luca
A22: 13 | B22: Simone
A23: 13 | B23: buff-x-bow
A24: 13 | B24: TinoGiusa
A25: 13 | B25: rasim01
A26: 13 | B26: Edoardo9
A27: 13 | B27: Francesco10
A28: 13 | B28: Floky23
A29: 13 | B29: maikol_lix
A30: 13 | B30: Elatanvsb108
... A36: 14 | B36: gionny
A37: 13 | B37: Fryck | C37: -12 | D37: -2 | E37: 3 | J37: -2 | K37: 1 | M37: -1 | N37: 3 | P37: -2 | Q37: 3 | R37: -16 | S37: -2 | T37: 3
A38: 13 | B38: IL MAGO NERO
B40: attacco basso
B41: attacco brutto
B42: no attacco
B43: ottimo attacco
B44: ottimo attacco
B45: attacco meh
B46: NO SONDAGGIO
...

Sheet avv
A1: 15 | B1: 18 | C1: 18 | D1: 17 | E1: 17 | F1: 16 | G1: 15
A2: 15 | B2: 16 | C2: 17 | D2: 16 | E2: 17 | F2: 16 | G2: 15
A3: 15 | B3: 15 | C3: 17 | D3: 15 | E3: 17 | F3: 15 | G3: 14
A4: 15 | B4: 15 | C4: 17 | D4: 15 | E4: 15 | F4: 15 | G4: 14
A5: 14 | B5: 15 | C5: 15 | D5: 15 | E5: 15 | F5: 15 | G5: 14
A6: 14 | B6: 15 | C6: 15 | D6: 15 | E6: 13 | F6: 15 | G6: 13
A7: 14 | B7: 15 | C7: 15 | D7: 15 | E7: 13 | F7: 15 | G7: 13
A8: 13 | B8: 15 | C8: 14 | D8: 15 | E8: 13 | F8: 15 | G8: 13
A9: 12 | B9: 14 | C9: 14 | D9: 14 | E9: 12 | F9: 15 | G9: 13
A10: 12 | B10: 14 | C10: 14 | D10: 14 | E10: 12 | F10: 14 | G10: 13
A11: 11 | B11: 13 | C11: 13 | D11: 14 | E11: 12 | F11: 14 | G11: 13
A12: 11 | B12: 13 | C12: 13 | D12: 14 | E12: 12 | F12: 14 | G12: 13
... A30: 10 | B30: 7 | C30: 10 | D30: 10 | E30: 8 | F30: 10 | G30: 9
A32: CWL2

Sheet partecipanti
A1: 16 | B1: xblade | N1: x | O1: ajejebrazorf | T1: GX king | X1: CWL 4 | AB1: CWL5 | AE1: riserve | AG1: fuori | AJ1: partecipanti | AL1: test | AN1: out | AO1: PARTECIPANTI | AP1: OUT | AQ1: TEST
A2: 15 | B2: marcojk007 | N2: x | O2: bigmc | T2: buff-x-bow | X2: andriu07 | Z2: Ale22 | AB2: Alessio9797 | AE2: omar | AG2: 655321 | AJ2: amazonie | AL2: gionny | AM2: 0/1 | AN2: dem | AO2: Amazonie | AP2: revolver | AQ2: PIPPII | AT2: x
A3: 15 | B3: dado | I3: 13 | J3: luigi01 | N3: x | O3: Dado | S3: Brazo | T3: Ale22 | X3: buff x-bow | Z3: Valh | AA3: fabiovesco | AB3: alhfmfh | AE3: Edoardo9 | AG3: Chabby | AJ3: anonymous | AL3: kle | AM3: 1/1 | AN3: subhom | AO3: Anto | AP3: chabby | AQ3: Kle | AT3: x
A4: 13 | B4: piegian99 | E4: maikol_lix | I4: 13 | J4: gionny | N4: x | O4: floky | S4: Chabby | X4: dado | Z4: SubOhm | AA4: Darvix | AB4: Amazonie | AE4: BigGiurz08 | AG4: EdoDodo | AJ4: anto | AL4: antony | AM4: 0/1 | AN4: chabby | AO4: BigMc23 | AP4: Dem | AQ4: cucco | AS4: v
A5: 13 | B5: stentaa | E5: ajejebrazorf | I5: 13 | J5: dela | N5: x | O5: GiornoBrando | S5: Cleopatra | X5: Floky23 | Z5: 655321 | AB5: antony | AE5: tinogiusa | AG5: maikol_lix | AJ5: bigmc | AL5: falcuns | AM5: 0/1 | AN5: edododo | AO5: buff-x-bow | AP5: EdoDodo | AQ5: fhhgggf | AT5: x
A6: 13 | B6: chabby | E6: edododo | I6: 12 | J6: nik | N6: x | O6: Giosan | S6: ER DANDI 1927 | X6: francesco | Z6: Giorgio | AA6: Diti | AG6: ER DANDI 1927 | AJ6: buffxbow | AL6: wolf | AO6: dado | AP6: vito | AS6: v
A7: 13 | B7: bigmc | I7: 12 | J7: buff x bow | N7: x | O7: haha | S7: Essenc3_kin4 | X7: Fryck | Z7: Chabby | AA7: KANEKI | AB7: BigMc23 | AG7: Fra | AJ7: dado | AL7: alhfmfh | AO7: Edoardo9 | AP7: matrox | AQ7: ajaz064 | AT7: x
A8: 13 | B8: brazo | N8: x | O8: hikarinorob | S8: Favij | X8: gionny | Z8: alhfmfh | AB8: buff x-bow | AG8: GGfresco_08 | AJ8: edoardo9 | AL8: ema alba | AO8: Floky23 | AS8: v
A9: 13 | B9: di gio | I9: 12 | J9: christian | N9: x | O9: Leo | S9: gionny | X9: GiornoBrando | Z9: EdoDodo | AB9: cucco | AG9: gionny | AJ9: el sushino | AL9: luka | AO9: Francesco10 | AQ9: roberto | AT9: x
A10: 13 | B10: luigi | N10: x | O10: Luigi | S10: Giorgio | X10: haha | Z10: GioStyle | AA10: tazio | AB10: dado | AG10: Mario | AJ10: floky23 | AL10: ajaz | AO10: GiornoBrando | AS10: v
A11: 13 | B11: giosan | I11: 12 | J11: dux | N11: x | O11: Luxor | S11: king | X11: HikariNoRob | Z11: Roberta | AA11: Leonida | AG11: Dasters79 | AJ11: francesco10 | AL11: re deo | AO11: haha | AQ11: SgherroMutante
A12: 12 | B12: pigiamone99 | I12: 12 | J12: fabio | N12: x | O12: maikol_lix | S12: Loris | X12: leo | AB12: Floky23 | AG12: salvo24 | AJ12: giornobrando | AL12: ggfresco | AO12: KAIZERS
A13: 12 | B13: sono io lakaka | I13: 12 | J13: daniele | N13: x | O13: Omar | S13: marcojk007 | X13: Luigi | AB13: GiornoBrando | AG13: Simone | AH13: x | AJ13: haha | AO13: leo (?) | AQ13: El sushino | AT13: x
A14: 12 | B14: floky | I14: 12 | J14: roberta | N14: x | O14: piegian99 | S14: MASCHI | X14: Luxor | AB14: haha | AG14: Spiderman | AJ14: juri | AK14: 1 | AO14: Luca | AQ14: ale 12 | AS14: v
A15: 12 | B15: serra | I15: 12 | J15: federico99 | N15: x | O15: pigiamone99 | S15: Roberta | X15: maikol_lix | AB15: HikariNoRob | AJ15: leo | AO15: Luigi | AQ15: zpercu | AT15: x
A16: 12 | B16: cleopatra | N16: x | O16: Robby | S16: sidcu js | X16: piegian99 | AB16: Kle | AG16: zordan | AJ16: luca | AO16: maikol_lix | AQ16: marcobeltra | AS16: v
A17: 12 | B17: leo | I17: 12 | J17: lord pucci | N17: x | O17: serra008 | S17: zine | X17: pigiamone99 | AB17: leo | AG17: SubOhm | AJ17: luigi | AO17: maragno
A18: 12 | B18: d 011 | I18: 11 | J18: juan falco | N18: x | O18: Simone | S18: danielpica | X18: PIPPII | AB18: Luca | AJ18: maikol lix | AO18: piegian99 | AT18: x
A19: 12 | B19: hikarinorob | I19: 11 | J19: dio animale | N19: x | O19: Staenta | S19: loris | X19: revolver | AB19: LucFir3 | AJ19: miriam miriam | AO19: rasim01 | AQ19: ale mugna | AS19: v
A20: 12 | B20: zombra | N20: x | O20: subohm | X20: RobbyCV | AB20: Luigi | AJ20: piegian99 | AO20: RobbyCV | AS20: v
A21: 12 | B21: kakko garau | N21: x | O21: thanos | X21: serra008 | AB21: MIRIAM MIRIAM | AJ21: pigiamone99 | AO21: Simone
A22: 12 | B22: heloo | N22: x | O22: Valh | X22: Stentaaa | AJ22: pippii | AO22: Stentaa
A23: 12 | B23: sidcu | N23: x | O23: Xblade | X23: th4nos | AB23: papi | AJ23: revolver | AO23: SubOhm
A24: 12 | B24: simone | N24: x | O24: xnullx | X24: xbladze | AB24: piegian99 | AJ24: robbycv | AK24: 1 | AO24: TinoGiusa
A25: 12 | B25: thanos | N25: x | O25: zombra | X25: zordan | AB25: pigiamone99 | AJ25: simone | AO25: xBlade
A26: 12 | B26: robbycv | N26: x | O26: queen of shadow | X26: Kle | AB26: PIPPII | AJ26: stentaa | AO26: xNullx
A27: 12 | B27: serena | N27: x | O27: sono io lakaka | X27: LucFir3 | AB27: revolver | AJ27: tinogiusa | AO27: Anonymus
A28: 12 | B28: haha | N28: x | O28: ggfd | X28: ER DANDI 1927 | AB28: RobbyCV | AJ28: xblade | AK28: 1 | AO28: elatan
A29: 12 | B29: luxor | N29: X | O29: ¥CATA¥ | AB29: Stentaaa | AJ29: xnullx | AO29: Akemi
X30: IL MAGO NERO | AB30: StepanYT Ita Uk
X31: favretto | AB31: xbladze
X32: BigMc23 | AB32: er samu
AB33: salvuz
AB34: juri

Sheet wars
A1: NAME | B1: ATK SKIP | C1: ZERO WAR ATK | D1: TOT WARS | E1: TOT STARS | F1: AVG STAR | G1: WAR-1 (1) | H1: WAR-1 (2) | I1: WAR-2 (1) | J1: WAR-2 (2) | K1: WAR-3 (1) | L1: WAR-3 (2) | M1: WAR-4 (1) | N1: WAR-4 (2) | O1: WAR-5 (1) | P1: WAR-5 (2) | Q1: WAR-6 (1) | R1: WAR-6 (2) | S1: WAR-7 (1) | T1: WAR-7 (2) | U1: WAR-8 (1) | V1: WAR-8 (2) | W1: WAR-9 (1) | X1: WAR-9 (2) | Y1: WAR-10 (1) | Z1: WAR-10 (2) | AA1: WAR-11 (1) | AB1: WAR-11 (2) | AC1: WAR-12(1) | AD1: WAR-12 (2) | AE1: WAR-13 (1) | AF1: WAR-13 (2) | AG1: WAR-14 (1) | AH1: WAR-14 (2) | AI1: WAR-15 (1) | AJ1: WAR-15 (2) | AK1: WAR-16 (1) | AL1: WAR-16 (2) | AM1: WAR-17 (1) | AN1: WAR-17 (2) | AO1: WAR-18 (1) | AP1: WAR-18 (2) | AQ1: WAR-19 (1) | AR1: WAR-19 (2) | AS1: WAR-20 (1) | AT1: WAR-20 (2) | AU1: WAR-21 (1) | AV1: WAR-21 (2) | AW1: WAR-22 (1) | AX1: WAR-22 (2) | AY1: WAR-23 (1) | AZ1: WAR-23 (2) | BA1: WAR-24 (1) | BB1: WAR-24 (2) | BC1: WAR-25 (1) | BD1: WAR-25 (2) | BE1: WAR-26 (1) | BF1: WAR-26 (2) | BG1: WAR-27 (1) | BH1: WAR-27 (2) | BI1: WAR-28 (1) | BJ1: WAR-28 (2) | BK1: WAR-29 (1) | BL1: WAR-29 (2) | BM1: WAR-30 (1) | BN1: WAR-30 (2) | BO1: WAR-31 (1) | BP1: WAR-31 (2) | BQ1: WAR-32 (1) | BR1: WAR-32 (2) | BS1: WAR-33 (1) | BT1: WAR-33 (2) | BU1: WAR-34 (1) | BV1: WAR-34 (2) | BW1: WAR-35 (1) | BX1: WAR-35 (2) | BY1: WAR-36 (1) | BZ1: WAR-36 (2) | CA1: WAR-37 (1) | CB1: WAR-37 (2) | CC1: WAR-38 (1) | CD1: WAR-38 (2) | CE1: WAR-39 (1) | CF1: WAR-39 (2) | CG1: WAR-40 (1) | CH1: WAR-40 (2) | CI1: WAR-41 (1) | CJ1: WAR-41 (2)
A2: 655321 | B2: 0 | C2: 0 | D2: 0 | E2: =SUM(G2:H2) | F2: =ROUND(AVERAGE(G2:H2),1)
A3: Amazonie | B3: 12 | C3: 6 | D3: 31 | E3: =SUM(G3:H3) | F3: =ROUND(AVERAGE(G3:H3),1) | G3: 3 | H3: 2 | AM3: 3 | AN3: 3 | AO3: 3 | AP3: 2 | AS3: 3 | AT3: 3 | AU3: 3 | AV3: 3 | AY3: 3 | AZ3: 3 | BA3: 3 | BB3: 3 | BC3: 3 | BD3: 2 | BE3: 3 | BF3: 3 | BG3: 2 | BH3: 2 | BQ3: 3 | BR3: 3 | BS3: 2 | BT3: 3 | BU3: 2 | BV3: 3 | BW3: SKIP | BX3: SKIP | BY3: 3 | BZ3: 3 | CA3: 3 | CB3: 3 | CC3: 3 | CD3: 3 | CE3: 3 | CF3: 3 | CI3: 2 | CJ3: 3
A4: buff x-bow | B4: 0 | C4: 0 | D4: 16 | E4: =SUM(G4:H4) | F4: =ROUND(AVERAGE(G4:H4),1) | G4: 3 | H4: 3 | K4: 3 | L4: 3 | M4: 3 | N4: 3 | Q4: 3 | R4: 3 | AC4: 2 | AD4: 2 | AM4: 3 | AN4: 3 | AU4: 3 | AV4: 3 | BC4: 3 | BD4: 3 | BE4: 3 | BF4: 3 | BG4: 3 | BH4: 2 | BU4: 3 | BV4: 3 | CA4: 3 | CB4: 3 | CC4: 3 | CD4: 3 | CE4: 3 | CF4: 3
A5: Chabby | B5: 1 | C5: 0 | D5: 1 | E5: =SUM(G5:H5) | F5: =ROUND(AVERAGE(G5:H5),1) | BA5: 3 | BB5: SKIP
A6: cucco | B6: 5 | C6: 2 | D6: 19 | E6: =SUM(G6:H6) | F6: =ROUND(AVERAGE(G6:H6),1) | G6: 2 | H6: SKIP | AM6: 1 | AN6: 3 | AO6: 3 | AP6: 3 | AS6: 0 | AT6: 0 | AU6: 2 | AV6: 3 | AY6: 3 | AZ6: 2 | BA6: 1 | BB6: 2 | BC6: 1 | BD6: 3 | BG6: 3 | BH6: 3 | BK6: 2 | BL6: 3 | BQ6: 3 | BR6: 2 | BS6: 2 | BT6: 2 | BU6: 3 | BV6: 3 | BW6: SKIP | BX6: SKIP | BY6: 2 | BZ6: 2 | CC6: 3 | CD6: 3 | CI6: 3 | CJ6: 3
A7: Edoardo9 | B7: 12 | C7: 4 | D7: 17 | E7: =SUM(G7:H7) | F7: =ROUND(AVERAGE(G7:H7),1) | G7: 3 | H7: SKIP | BO7: 3 | BP7: 3 | BQ7: 1 | BR7: SKIP | BS7: 3 | BT7: SKIP | BU7: 1 | BV7: 3 | CA7: 3 | CB7: SKIP | CC7: 3 | CD7: 3 | CI7: 2 | CJ7: 0
A8: EdoDodo | B8: 0 | C8: 0 | D8: 0 | E8: =SUM(G8:H8) | F8: =ROUND(AVERAGE(G8:H8),1)
A9: GiornoBrando | B9: 13 | C9: 5 | D9: 31 | E9: =SUM(G9:H9) | F9: =ROUND(AVERAGE(G9:H9),1) | G9: 1 | H9: 3 | I9: 3 | J9: 1 | K9: 3 | L9: 3 | O9: 3 | P9: 1 | Q9: 3 | R9: 3 | U9: 3 | V9: 1 | AA9: 3 | AB9: 3 | AC9: 2 | AD9: 2 | AE9: 3 | AF9: SKIP | AI9: SKIP | AJ9: SKIP | AK9: 3 | AL9: 2 | AM9: 3 | AN9: 3 | AO9: 1 | AP9: 1 | AS9: 3 | AT9: 3 | AU9: 3 | AV9: 3 | AY9: 3 | AZ9: 3 | BA9: 1 | BB9: SKIP | BC9: 3 | BD9: 3 | BI9: 3 | BJ9: 3 | BK9: 1 | BL9: SKIP | BO9: 3 | BP9: 2 | BU9: 3 | BV9: 3 | BW9: SKIP | BX9: SKIP | BY9: 3 | BZ9: 1
A10: haha | B10: 4 | C10: 2 | D10: 19 | E10: =SUM(G10:H10) | F10: =ROUND(AVERAGE(G10:H10),1) | G10: 3 | H10: 3 | S10: 2 | T10: 3 | W10: 2 | X10: 2 | Y10: 3 | Z10: 3 | AA10: 3 | AB10: 3 | AC10: 3 | AD10: 3 | AI10: SKIP | AJ10: SKIP | AK10: 3 | AL10: 3 | AM10: 2 | AN10: 2 | AU10: 3 | AV10: 3 | BA10: 1 | BB10: 1 | BQ10: 3 | BR10: 3 | BS10: 3 | BT10: 3 | BU10: 3 | BV10: 3 | BW10: SKIP | BX10: SKIP | BY10: 3 | BZ10: 3 | CA10: 3 | CB10: 3 | CC10: 2 | CD10: 3 | CE10: 3 | CF10: 2
A11: Kle | B11: 1 | C11: 0 | D11: 6 | E11: =SUM(G11:H11) | F11: =ROUND(AVERAGE(G11:H11),1) | AM11: 2 | AN11: 2 | AO11: 3 | AP11: 3 | AS11: 2 | AT11: 2 | AY11: 3 | AZ11: 2 | BE11: 3 | BF11: SKIP | BS11: 2 | BT11: 3
A12: Luigi | B12: 14 | C12: 6 | D12: 26 | E12: =SUM(G12:H12) | F12: =ROUND(AVERAGE(G12:H12),1) | G12: SKIP | H12: SKIP | I12: 2 | J12: SKIP | M12: 3 | N12: 1 | O12: 3 | P12: 3 | Q12: 2 | R12: SKIP | W12: 2 | X12: 2 | AA12: 3 | AB12: 2 | AC12: 2 | AD12: 3 | AO12: 0 | AP12: 1 | AU12: 3 | AV12: 1 | AY12: 3 | AZ12: 3 | BA12: 2 | BB12: 2 | BG12: 2 | BH12: 3 | BK12: 3 | BL12: 2 | BO12: 2 | BP12: 3 | BS12: 2 | BT12: 3 | CC12: 3 | CD12: 3 | CE12: SKIP | CF12: SKIP | CI12: 3 | CJ12: 3
A13: maikol_lix | B13: 22 | C13: 3 | D13: 27 | E13: =SUM(G13:H13) | F13: =ROUND(AVERAGE(G13:H13),1) | G13: 3 | H13: 2 | I13: 3 | J13: 3 | O13: 3 | P13: SKIP | S13: 2 | T13: SKIP | W13: 3 | X13: 2 | AA13: 3 | AB13: SKIP | AE13: 3 | AF13: SKIP | AI13: SKIP | AJ13: SKIP | AK13: 3 | AL13: 3 | AO13: 3 | AP13: SKIP | AS13: 3 | AT13: 2 | BA13: 3 | BB13: SKIP | BE13: 3 | BF13: SKIP | BG13: 3 | BH13: 3 | BK13: 3 | BL13: SKIP | BO13: 3 | BP13: 3 | BU13: 3 | BV13: SKIP | BW13: SKIP | BX13: SKIP | BY13: 3 | BZ13: SKIP | CA13: 2 | CB13: SKIP | CC13: 3 | CD13: SKIP | CE13: 3 | CF13: SKIP | CI13: 3 | CJ13: SKIP
A14: RobbyCV | B14: 6 | C14: 3 | D14: 17 | E14: =SUM(G14:H14) | F14: =ROUND(AVERAGE(G14:H14),1) | G14: 3 | H14: 0 | I14: SKIP | J14: SKIP | K14: 3 | L14: 3 | M14: 1 | N14: 1 | O14: 0 | P14: SKIP | Q14: 2 | R14: SKIP | W14: 3 | X14: 3 | Y14: 3 | Z14: 2 | AA14: 3 | AB14: 1 | AC14: 1 | AD14: 1 | AE14: 3 | AF14: 2 | AM14: 3 | AN14: 2 | BO14: 1 | BP14: 1 | BQ14: 3 | BR14: 1 | BU14: SKIP | BV14: SKIP | CA14: 3 | CB14: 2
A15: Simone | B15: 2 | C15: 1 | D15: 8 | E15: =SUM(G15:H15) | F15: =ROUND(AVERAGE(G15:H15),1) | G15: 3 | H15: 3 | I15: 2 | J15: 3 | O15: 3 | P15: 3 | Q15: 3 | R15: 3 | AU15: 3 | AV15: 3 | BA15: 3 | BB15: 2 | BE15: 3 | BF15: 2 | BG15: SKIP | BH15: SKIP
A16: SubOhm | B16: 0 | C16: 0 | D16: 1 | E16: =SUM(G16:H16) | F16: =ROUND(AVERAGE(G16:H16),1) | AS16: 3 | AT16: 2
A17: xbladze | B17: 23 | C17: 11 | D17: 35 | E17: =SUM(G17:H17) | F17: =ROUND(AVERAGE(G17:H17),1) | G17: SKIP | H17: SKIP | I17: 2 | J17: 3 | K17: SKIP | L17: SKIP | O17: 3 | P17: 2 | Q17: 3 | R17: 3 | S17: 2 | T17: 2 | W17: 3 | X17: 3 | Y17: 2 | Z17: 3 | AA17: 3 | AB17: 2 | AC17: 2 | AD17: 3 | AI17: SKIP | AJ17: SKIP | AK17: 2 | AL17: 3 | AM17: 2 | AN17: 3 | AS17: 3 | AT17: 3 | AU17: 3 | AV17: 3 | BA17: 2 | BB17: 3 | BC17: 3 | BD17: 3 | BE17: 3 | BF17: 3 | BG17: 2 | BH17: 3 | BK17: 3 | BL17: 2 | BM17: 3 | BN17: 3 | BO17: 3 | BP17: 3 | BQ17: SKIP | BR17: SKIP | BS17: SKIP | BT17: SKIP | BU17: 2 | BV17: 1 | CC17: SKIP | CD17: SKIP | CE17: SKIP | CF17: SKIP | CI17: SKIP | CJ17: SKIP
A18: Anonymous | B18: 2 | C18: 1 | D18: 1 | E18: =SUM(G18:H18) | F18: =ROUND(AVERAGE(G18:H18),1) | CC18: SKIP | CD18: SKIP
A19: ajaz064 | B19: 8 | C19: 4 | D19: 5 | E19: =SUM(G19:H19) | F19: =ROUND(AVERAGE(G19:H19),1) | G19: 3 | H19: 2
A20: xNullx | B20: 10 | C20: 5 | D20: 12 | E20: =SUM(G20:H20) | F20: =ROUND(AVERAGE(G20:H20),1) | G20: 3 | H20: 3
A21: fhhgggf | B21: 9 | C21: 4 | D21: 8 | E21: =SUM(G21:H21) | F21: =ROUND(AVERAGE(G21:H21),1) | G21: 3 | H21: 3
A22: maragno | B22: 1 | C22: 0 | D22: 3 | E22: =SUM(G22:H22) | F22: =ROUND(AVERAGE(G22:H22),1) | G22: 1 | H22: SKIP
A23: Akemi | B23: 0 | C23: 0 | D23: 0 | E23: =SUM(G23:H23) | F23: =ROUND(AVERAGE(G23:H23),1)
A24: Elatanvsb108 | B24: 1 | C24: 0 | D24: 2 | E24: =SUM(G24:H24) | F24: =ROUND(AVERAGE(G24:H24),1) | G24: 2 | H24: 2
